Workbook

Sheet PostQuestionnaire.csv
B1: User id | C1: Question 1 | D1: Question 2 | E1: Question 3 | F1: Question 4 | G1: Question 5 | H1: Question 6 | I1: Question 7 | J1: Question 8 | K1: Question 9 | L1: Question 10 | M1: Question 11 | N1: Question 12 | O1: Question 13 | P1: Question 14 | Q1: Question 15 | R1: Question 16 | S1: Question 17 | T1: Question 18 | U1: Question 19 | V1: Question 20 | W1: Question 21 | X1: Question 22 | Y1: Question 23 | Z1: Question 24 | AA1: Question 25
A2: =COUNTIF(Sheet1!$A$2:$A$17, B1) -> 0 | B2: 87 | C2: 5 | D2: 5 | E2: 5 | F2: 5 | G2: 5 | H2: 2 | I2: 2 | J2: 2 | K2: 2 | L2: 5 | M2: 5 | N2: 5 | O2: 5 | P2: 4 | Q2: 2 | R2: 4 | S2: 4 | T2: 4 | U2: 4 | V2: 3 | W2: The clear visual aspect | X2: waited and waited but couldn't find partners that were available and online the same times I was. | Y2: I found that when I would click and tell it to move or add a arrow it would only work half the time | AA2: I enjoyed it but found that even though I had the nodes in the right order it would say that they weren't then I would repeat the exact same thing and it would work after the 3rd or 4th time submitting.
A3: =COUNTIF(Sheet1!$A$2:$A$17, B2) -> 0 | B3: 86 | C3: 5 | D3: 5 | E3: 5 | F3: 5 | G3: 5 | H3: 5 | I3: 5 | J3: 5 | K3: 5 | L3: 5 | M3: 4 | N3: 4 | O3: 4 | P3: 5 | Q3: 5 | R3: 3 | S3: 4 | T3: 3 | U3: 4 | V3: 3 | W3: Minimalistic. | X3: N/A | Y3: Correct answers sometimes don't work | Z3: but work the next try | AA3: like the last question of the first section. | AB3: N/A | AC3: The 2 I've left unanswered are never register the correct answer.
A4: =COUNTIF(Sheet1!$A$2:$A$17, B3) -> 0 | B4: 85 | C4: 4 | D4: 5 | E4: 4 | F4: 4 | G4: 4 | H4: 4 | I4: 3 | J4: 4 | K4: 4 | L4: 4 | M4: 4 | N4: 4 | O4: 4 | P4: 5 | Q4: 5 | R4: 4 | S4: 4 | T4: 4 | U4: 3 | V4: 3 | W4: Even though I did not use it | X4: the collaborative part of the system seemed the most intuative | Y4: Did not use | Z4: Surves its purpose well as it currently is | AA4: Did not use but voice chat would be great | AB4: Question 4 in the Removing Nodes Section kept saying I got the wrong answer when done with the correct procedure
A5: =COUNTIF(Sheet1!$A$2:$A$17, B4) -> 0 | B5: 83 | C5: 3 | D5: 3 | E5: 3 | F5: 4 | G5: 4 | H5: 4 | I5: 4 | J5: 4 | K5: 3 | L5: 4 | M5: 4 | N5: 4 | O5: 4 | P5: 3 | Q5: 4 | R5: 3 | S5: 4 | T5: 4 | U5: 3 | V5: 2 | W5: Simple and easy to use | X5: very straightforward and has a basic interface | Y5: I did not manage to collaborate | Z5: i onl know one person in this class and they already did work with someone else | AA5: I suggest just a tad bit more explaining may be necessary | AB5: it was a little confusing the first time i used it but i got the hang of it eventually | AC5: Didn't use the collaborative part of the system | AD5: It was definitely a useful experience | AE5: helped me better understand the implementation of linked lists | AF5: i am only fuzzy about the moving of nodes in a linked list
A6: =COUNTIF(Sheet1!$A$2:$A$17, B5) -> 0 | B6: 82 | C6: 3 | D6: 3 | E6: 3 | F6: 3 | G6: 3 | H6: 3 | I6: 2 | J6: 2 | K6: 2 | L6: 3 | M6: 3 | N6: 4 | O6: 3 | P6: 3 | Q6: 3 | R6: 4 | S6: 3 | T6: 3 | U6: 3 | V6: 3 | W6: ease of use | X6: not sure what this is? | Y6: sometimes the arrows didnt cooperate | Z6: none | AA6: thanks
A7: =COUNTIF(Sheet1!$A$2:$A$17, B6) -> 0 | B7: 81 | C7: 4 | D7: 2 | E7: 4 | F7: 4 | G7: 4 | H7: 2 | I7: 2 | J7: 2 | K7: 4 | L7: 5 | M7: 5 | N7: 4 | O7: 4 | P7: 2 | Q7: 2 | R7: 4 | S7: 4 | T7: 4 | U7: 4 | V7: 3 | W7: The diagrams with the arrows actually helped improve my understanding quite a bit | X7: I didn't collaborate :( | Y7: System's a little buggy | Z7: it froze a couple of times and wouldn't move arrows | AA7: Not sure! | AB7: Sometimes the clicks wouldn't register which would result in me getting a question wrong.
A8: =COUNTIF(Sheet1!$A$2:$A$17, B7) -> 0 | B8: 80 | C8: 5 | D8: 4 | E8: 5 | F8: 5 | G8: 5 | H8: 5 | I8: 4 | J8: 5 | K8: 4 | L8: 5 | M8: 5 | N8: 4 | O8: 5 | P8: 4 | Q8: 4 | R8: 3 | S8: 4 | T8: 4 | U8: 4 | V8: 3 | W8: Visul aid | X8: n/a | Y8: check algorithm | Z8: there were some errors
A9: =COUNTIF(Sheet1!$A$2:$A$17, B8) -> 0 | B9: 79 | C9: 4 | D9: 3 | E9: 4 | F9: 4 | G9: 4 | H9: 3 | I9: 4 | J9: 4 | K9: 4 | L9: 4 | M9: 4 | N9: 4 | O9: 4 | P9: 4 | Q9: 4 | R9: 4 | S9: 2 | T9: 2 | U9: 2 | V9: 4 | W9: simplicity | X9: i did not | Y9: it crashed a few times | Z9: could be slightly more aesthetically pleasing. more diverse problems and other concepts | AA9: i did not | AB9: crashed a few times | AC9: i think i got a few right that it marked wrong | AD9: but overall good program.
A10: =COUNTIF(Sheet1!$A$2:$A$17, B9) -> 0 | B10: 78 | C10: 4 | D10: 4 | E10: 4 | F10: 4 | G10: 4 | H10: 4 | I10: 4 | J10: 4 | K10: 4 | L10: 4 | M10: 4 | N10: 4 | O10: 3 | P10: 3 | Q10: 4 | R10: 4 | S10: 4 | T10: 3 | U10: 3 | V10: 4 | W10: easy to use | X10: not too sure | Y10: its fine as is | Z10: its fine as is
A11: =COUNTIF(Sheet1!$A$2:$A$17, B10) -> 0 | B11: 76 | C11: 4 | D11: 3 | E11: 5 | F11: 4 | G11: 5 | H11: 3 | I11: 3 | J11: 3 | K11: 5 | L11: 5 | M11: 5 | N11: 5 | O11: 4 | P11: 5 | Q11: 3 | R11: 4 | S11: 4 | T11: 3 | U11: 4 | V11: 2 | W11: Helps me to visualize how the linked list is working | Y11: It would be nice if in the section for rearranging nodes it would let me create a pointer from a node so that I could reconnect it to other nodes
A12: =COUNTIF(Sheet1!$A$2:$A$17, B11) -> 1 | B12: 75 | C12: 4 | D12: 4 | E12: 4 | F12: 4 | G12: 4 | H12: 4 | I12: 4 | J12: 4 | K12: 4 | L12: 4 | M12: 4 | N12: 4 | O12: 4 | P12: 3 | Q12: 3 | R12: 3 | S12: 4 | T12: 4 | U12: 4 | V12: 4 | Y12: More clear instructions.
A13: =COUNTIF(Sheet1!$A$2:$A$17, B12) -> 0 | B13: 74 | C13: 3 | D13: 3 | E13: 3 | G13: 3 | H13: 3 | I13: 3 | J13: 3 | L13: 3 | M13: 3 | N13: 4 | O13: 3 | P13: 4 | Q13: 4 | R13: 3 | S13: 3 | T13: 3 | U13: 3 | V13: 3 | W13: It was relatively straightforward. | Y13: Add more diversity into the problems | Z13: it got a bit repetitive. | AB13: One of the adding problems talked about having 3 boxes at the end but there needed to be five and another adding one didn't accept my answer as correct the first time even though it was the same the second time.
A14: =COUNTIF(Sheet1!$A$2:$A$17, B13) -> 0 | B14: 73 | C14: 4 | D14: 3 | E14: 4 | F14: 4 | G14: 4 | H14: 4 | I14: 4 | J14: 4 | K14: 4 | L14: 4 | M14: 4 | N14: 4 | O14: 4 | P14: 4 | Q14: 3 | R14: 5 | S14: 4 | T14: 5 | U14: 4 | V14: 3 | W14: SImple to navigate | X14: easy to use | Y14: and engaging. Feels like a puzzle game rather than work. | Z14: - | AA14: - | AB14: - | AC14: Questions would | AD14: on occasion | AE14: return that they had been answered incorrectly when they were infact correctly answered (mostly the re-ordering lists questions)
A15: =COUNTIF(Sheet1!$A$2:$A$17, B14) -> 0 | B15: 71 | C15: 3 | D15: 2 | E15: 4 | F15: 2 | G15: 4 | H15: 3 | I15: 3 | J15: 4 | K15: 2 | L15: 3 | M15: 5 | N15: 4 | O15: 4 | P15: 5 | Q15: 5 | R15: 5 | S15: 2 | T15: 4 | U15: 4 | V15: 3 | W15: the fact that it is interactive helps people who don't understand the main idea comprehend it better. | X15: the best part was that we can use the program for help from other users who are willing to help. | Y15: I think adding an undo button will do. | Z15: when the user goes to a question | AA15: the partner should instantly be with working with him. | AB15: I enjoyed working on it. It sort of reminds me of some games I play.
A16: =COUNTIF(Sheet1!$A$2:$A$17, B15) -> 1 | B16: 70 | C16: 5 | D16: 5 | E16: 5 | F16: 5 | G16: 5 | H16: 5 | I16: 5 | J16: 5 | K16: 5 | L16: 5 | M16: 5 | N16: 5 | O16: 5 | P16: 5 | Q16: 5 | R16: 5 | S16: 5 | T16: 4 | U16: 3 | V16: 3 | W16: It is a creative idea and can be very useful if refined | Y16: The system tends to freeze or slows down sometimes. | AA16: The system was helpful.
A17: =COUNTIF(Sheet1!$A$2:$A$17, B16) -> 1 | B17: 69 | C17: 4 | D17: 4 | E17: 4 | F17: 4 | G17: 4 | H17: 4 | I17: 4 | J17: 4 | K17: 4 | L17: 4 | M17: 4 | N17: 4 | O17: 4 | P17: 4 | Q17: 4 | R17: 4 | S17: 4 | T17: 4 | U17: 2 | V17: 4 | W17: Easy enough to get bonus mark. | X17: You can work with someone which improves teamwork skills. | Y17: If the system responds quickly I will like it more. | Z17: The partner window pop-up every time the partner joined or starts a question | AA17: it makes me hard to see the left bottom part of my screen. | AB17: When I do the removing part | AC17: the nodes can somehow move automatically and then the system died | AD17: which makes me have to start over.
A18: =COUNTIF(Sheet1!$A$2:$A$17, B17) -> 1 | B18: 68 | C18: 4 | D18: 4 | E18: 4 | F18: 4 | G18: 4 | H18: 4 | I18: 4 | J18: 4 | K18: 3 | L18: 3 | M18: 3 | N18: 3 | O18: 3 | P18: 3 | Q18: 2 | R18: 3 | S18: 4 | T18: 5 | U18: 5 | V18: 5 | W18: Introduction. | Y18: Make the introduction much clearer. | AA18: So far | AB18: so good.
A19: =COUNTIF(Sheet1!$A$2:$A$17, B18) -> 0 | B19: 67 | C19: 4 | D19: 4 | E19: 4 | F19: 4 | G19: 4 | H19: 4 | I19: 4 | J19: 4 | K19: 4 | L19: 4 | M19: 4 | N19: 4 | O19: 4 | P19: 3 | Q19: 2 | R19: 3 | S19: 4 | T19: 4 | U19: 4 | V19: 4 | W19: Makes it easier to visualize | X19: Being able to work out the problems with someone else who can see what is going on. | Y19: The chat between partners is clunky as it always drops down to bottom but doesnt keep refereshing correctly (hard to explain in words). When adding a temporary variable the system gets really messed. If need I can provide in more detail the issues I saw in the system. | Z19: The moving of nodes is messy and temporary variables are out of control. | AA19: Quite a few issues involved but too difficult to explain all of them in this questionnaire.
A20: =COUNTIF(Sheet1!$A$2:$A$17, B19) -> 1 | B20: 65 | C20: 3 | D20: 3 | E20: 3 | F20: 3 | G20: 3 | H20: 3 | I20: 3 | J20: 3 | K20: 4 | L20: 3 | M20: 4 | N20: 3 | O20: 3 | P20: 4 | Q20: 2 | R20: 1 | S20: 2 | T20: 3 | U20: 3 | V20: 2 | W20: It was easy. | X20: I didn't use them but I liked that little available partners thing. | Y20: The first reordering question was broken and would not let me move pointers. In a fit of frustration I just clicked submit and even though it was wrong it marked it as right? So there's that. | AA20: It was easy but it was a little TOO easy almost mindlessly so.
A21: =COUNTIF(Sheet1!$A$2:$A$17, B20) -> 0 | B21: 64 | C21: 2 | D21: 2 | E21: 2 | F21: 2 | G21: 2 | H21: 2 | I21: 2 | J21: 2 | L21: 2 | M21: 2 | N21: 2 | O21: 2 | P21: 2 | Q21: 2 | R21: 2 | S21: 2 | T21: 2 | U21: 2 | V21: 3 | W21: It worked | Y21: Did not really teach me anything about linked list. Just seemed like moving blocks around. In my opinion you cant make it any better. | AA21: It was made well I just didn't find it useful.
A22: =COUNTIF(Sheet1!$A$2:$A$17, B21) -> 0 | B22: 63 | C22: 4 | D22: 4 | E22: 4 | F22: 3 | G22: 4 | H22: 4 | I22: 3 | J22: 4 | K22: 4 | L22: 4 | M22: 4 | N22: 4 | O22: 4 | P22: 5 | Q22: 5 | R22: 4 | S22: 3 | T22: 3 | U22: 3 | V22: 3 | W22: Simple usage | X22: n/a | Y22: It told me they werent in alphabetical order but they totally were. | Z22: n/a
A23: =COUNTIF(Sheet1!$A$2:$A$17, B22) -> 0 | B23: 61 | C23: 4 | D23: 4 | E23: 4 | F23: 4 | G23: 4 | H23: 4 | I23: 4 | J23: 4 | K23: 4 | L23: 4 | M23: 4 | N23: 4 | O23: 4 | P23: 3 | Q23: 2 | R23: 3 | S23: 4 | T23: 3 | U23: 4 | V23: 4 | W23: Easy to visualize how the concept works | X23: Being able to discuss the questions and learn from them | Y23: Provide the undo button | Z23: The pop up window for messages is smaller so that it will not cover the commands. | AA23: It is not too complicated and quite easy to use. The connection between two partners working on a question is quite slow.
A24: =COUNTIF(Sheet1!$A$2:$A$17, B23) -> 1 | B24: 58 | C24: 4 | D24: 4 | E24: 4 | F24: 4 | G24: 4 | H24: 4 | I24: 4 | J24: 4 | K24: 4 | L24: 4 | M24: 4 | N24: 4 | O24: 4 | P24: 4 | Q24: 4 | R24: 4 | S24: 4 | T24: 4 | U24: 4 | V24: 4 | W24: change the order of the elements | X24: N/A | Y24: not smart enough | Z24: N/A | AA24: N/A
A25: =COUNTIF(Sheet1!$A$2:$A$17, B24) -> 0 | B25: 57 | C25: 5 | D25: 4 | E25: 5 | F25: 2 | G25: 5 | H25: 5 | I25: 2 | J25: 4 | K25: 4 | L25: 4 | M25: 4 | N25: 4 | O25: 4 | P25: 5 | Q25: 5 | R25: 3 | S25: 4 | T25: 4 | U25: 4 | V25: 3
A26: =COUNTIF(Sheet1!$A$2:$A$17, B25) -> 0 | B26: 56 | C26: 3 | D26: 3 | E26: 3 | F26: 3 | G26: 3 | H26: 3 | I26: 3 | J26: 3 | K26: 3 | L26: 3 | M26: 3 | N26: 3 | O26: 1 | P26: 1 | Q26: 1 | R26: 1 | S26: 1 | T26: 1 | U26: 1 | V26: 3 | Y26: The arrows are hard to use | Z26: the diagrams just keep getting messed up for no reason
A27: =COUNTIF(Sheet1!$A$2:$A$17, B26) -> 1 | B27: 55 | C27: 5 | D27: 5 | E27: 5 | F27: 5 | G27: 5 | H27: 5 | I27: 5 | J27: 5 | K27: 5 | L27: 1 | M27: 1 | N27: 1 | O27: 1 | P27: 1 | Q27: 1 | R27: 1 | S27: 1 | T27: 1 | U27: 1 | V27: 1 | W27: when it didn't bug out | Y27: fix bugs had to submit one thing 15 times
A28: =COUNTIF(Sheet1!$A$2:$A$17, B27) -> 0 | B28: 52 | C28: 4 | D28: 3 | E28: 4 | F28: 4 | G28: 4 | H28: 3 | I28: 3 | J28: 3 | K28: 3 | L28: 5 | M28: 5 | N28: 4 | O28: 4 | P28: 4 | Q28: 4 | R28: 4 | S28: 4 | T28: 4 | U28: 4 | V28: 4 | W28: Kept allowing you to try no matter how many times you submitted an answer | X28: Didn't use them? | Y28: It would be interesting if you could add in code | Z28: because thats what we get tested on for exams. It was nice seeing how it all worked with diagrams like you did; however | AA28: I didn't actually practice any code so I don't know if I am doing that properly | AB28: Didn't use them | AC28: Good work!
A29: =COUNTIF(Sheet1!$A$2:$A$17, B28) -> 0 | B29: 49 | C29: 5 | D29: 4 | E29: 5 | F29: 5 | G29: 5 | H29: 5 | I29: 5 | J29: 4 | L29: 5 | M29: 4 | O29: 4 | P29: 3 | Q29: 3 | R29: 4 | S29: 3 | T29: 4 | U29: 3 | V29: 3 | W29: Colors | X29: N/A | Y29: Instructions could be made in point form | Z29: video tutorial might work. Recommend users to clear cache or disable plugins/add-on on browser as troubleshooting. | AA29: N/A | AB29: Great experience | AC29: a little too easy. Sometimes the answer is right but wrong message appeared.
A30: =COUNTIF(Sheet1!$A$2:$A$17, B29) -> 0 | B30: 45 | C30: 4 | D30: 4 | E30: 4 | F30: 4 | G30: 4 | H30: 4 | I30: 4 | J30: 4 | K30: 4 | L30: 4 | M30: 4 | N30: 4 | O30: 4 | P30: 4 | Q30: 4 | R30: 4 | S30: 4 | T30: 4 | U30: 4 | V30: 3 | W30: Hands on experience with a visual form of linked lists | X30: N/A | Y30: There were some glitches | Z30: N/A
A31: =COUNTIF(Sheet1!$A$2:$A$17, B30) -> 0 | B31: 43 | C31: 4 | D31: 3 | E31: 4 | F31: 3 | G31: 4 | H31: 3 | I31: 3 | J31: 3 | K31: 4 | L31: 4 | M31: 4 | N31: 4 | O31: 3 | P31: 2 | Q31: 3 | R31: 3 | S31: 3 | T31: 3 | U31: 3 | V31: 2 | W31: User interface is really well put together. | X31: I tried to | Y31: but it didn't work. | Z31: Just some minor little issues | AA31: and the partner system didn't work for me. | AB31: N/A | AC31: Well done Matt!
A32: =COUNTIF(Sheet1!$A$2:$A$17, B31) -> 0 | B32: 37 | C32: 1 | D32: 3 | E32: 3 | F32: 3 | G32: 4 | H32: 3 | I32: 4 | J32: 3 | K32: 3 | L32: 4 | M32: 4 | N32: 4 | O32: 4 | P32: 3 | Q32: 4 | R32: 2 | S32: 4 | T32: 4 | U32: 3 | V32: 4 | W32: Earn the bonus mark | X32: two are better than one | Y32: the system is not stable and diagram will automatically move without my command even i dont have a partner. | Z32: when two people are working together | AA32: the diagram should not be moved together. | AB32: maybe more detailed explanations
A33: =COUNTIF(Sheet1!$A$2:$A$17, B32) -> 1 | B33: 36 | C33: 5 | D33: 5 | E33: 5 | F33: 5 | G33: 5 | H33: 5 | I33: 5 | J33: 5 | K33: 5 | L33: 5 | M33: 5 | N33: 5 | O33: 5 | P33: 5 | Q33: 5 | R33: 3 | S33: 3 | T33: 4 | U33: 2 | V33: 3 | W33: A good visual representation of linked lists. | X33: N/A didn't use. | Y33: Sometimes the system would say I got a question wrong when I did it correctly. | Z33: N/A | AA33: Thanks.
A34: =COUNTIF(Sheet1!$A$2:$A$17, B33) -> 0 | B34: 35 | C34: 4 | D34: 3 | E34: 4 | F34: 4 | G34: 4 | H34: 3 | I34: 4 | J34: 3 | K34: 5 | L34: 5 | M34: 5 | N34: 5 | O34: 5 | P34: 3 | Q34: 1 | R34: 1 | S34: 4 | T34: 3 | U34: 2 | V34: 2 | W34: visually showing how nodes work | Y34: less glitchy crap | Z34: both for the interactive diagrams and for the chat window | AB34: glitchy | AC34: but useful
A35: =COUNTIF(Sheet1!$A$2:$A$17, B34) -> 1 | B35: 34 | C35: 3 | D35: 3 | E35: 3 | F35: 3 | G35: 3 | H35: 3 | I35: 3 | J35: 3 | K35: 3 | L35: 3 | M35: 3 | N35: 1 | O35: 1 | P35: 1 | Q35: 1 | R35: 1 | S35: 1 | T35: 1 | U35: 1 | V35: 4 | W35: The end | X35: Getting help when stuck | Y35: The nodes move around by themselves | Z35: even when both my partner and I are not touching the keyboard | AA35: Long delay between what my partner sees on the screen | AB35: I like data structures
A36: =COUNTIF(Sheet1!$A$2:$A$17, B35) -> 1 | B36: 33 | C36: 4 | D36: 3 | E36: 4 | F36: 4 | G36: 3 | H36: 3 | I36: 2 | J36: 2 | K36: 4 | L36: 3 | M36: 4 | N36: 4 | O36: 3 | P36: 3 | Q36: 1 | R36: 1 | S36: 1 | T36: 1 | U36: 1 | V36: 1 | W36: it was simple to understand what to do | X36: i tried but it was impossible it would not work | Y36: it was very glitchy and i did the last 4 right a ton of times but no matter what it wouldnt accept it | Z36: make it work properly | AA36: it hardly worked
A37: =COUNTIF(Sheet1!$A$2:$A$17, B36) -> 0 | B37: 32 | C37: 3 | D37: 3 | E37: 3 | F37: 3 | G37: 3 | H37: 3 | I37: 3 | J37: 3 | K37: 2 | L37: 2 | M37: 2 | N37: 2 | O37: 2 | P37: 2 | Q37: 1 | R37: 2 | S37: 2 | T37: 3 | U37: 2 | V37: 1 | W37: It was easy | X37: I tried using but it wouldn't work | Y37: remove the bugs | Z37: would enter in questions right but get them wrong and sometimes buttons didnt work | AA37: make it work
A38: =COUNTIF(Sheet1!$A$2:$A$17, B37) -> 0 | B38: 30 | C38: 5 | D38: 5 | E38: 4 | F38: 4 | G38: 4 | H38: 3 | I38: 4 | J38: 3 | K38: 4 | L38: 4 | M38: 4 | N38: 3 | O38: 3 | P38: 4 | Q38: 4 | R38: 4 | S38: 3 | T38: 3 | U38: 4 | V38: 4 | W38: The fact that it was so easy | X38: I didn't use the collab part. | Y38: Make it less glitchy and fix the bug errors. | Z38: Didn't use collab part. | AA38: I disliked the portions where the project would glitch out on you and say you have done it wrong when you inserted the correct answers | AB38: forcing you to exit the question and re-enter it.
A39: =COUNTIF(Sheet1!$A$2:$A$17, B38) -> 0 | B39: 27 | C39: 5 | D39: 4 | E39: 5 | F39: 5 | G39: 5 | H39: 4 | I39: 4 | J39: 3 | K39: 5 | L39: 4 | M39: 4 | N39: 4 | O39: 5 | P39: 4 | Q39: 3 | R39: 4 | S39: 4 | T39: 4 | U39: 4 | V39: 4 | W39: the visual representation | X39: I did not use any of the collaborative parts | Y39: At least 5 times I solved the problem correctly and the system rejected my solution. After trying the same solution for the third time | Z39: it finally accepted my solution | AA39: Did not use it. | AB39: You have two 25's in this questionnaire.
A40: =COUNTIF(Sheet1!$A$2:$A$17, B39) -> 0 | B40: 26 | C40: 5 | D40: 4 | E40: 5 | F40: 5 | G40: 5 | H40: 4 | I40: 4 | J40: 4 | K40: 5 | L40: 4 | M40: 4 | N40: 4 | O40: 4 | P40: 3 | Q40: 3 | R40: 3 | S40: 3 | T40: 4 | U40: 3 | V40: 3 | W40: It gives a good visual representation of what i am doing when coding linked lists | X40: Didn't have to figure it all out by myself | Y40: Doing it with a partner was extremely buggy and for the last few question I had to turn it off to make it possible to complete. It worked well enough without the parter aspect. Sometimes the tiles didnt have numbers when it said it should this was usually fixed by restarting that excersize. | Z40: The chat box was very buggy and often glitched out the question while using it. I'm not sure if it was suposed to be where you both did the question editiing the same boxes but if it was there was a very high latency and was very buggy. | AA40: It was decent aside from the partner aspect of it and a few minor bugs that could be fixed by restarting that question. Also i would sometimes get right answers even if i knew they were wrong on a small number of questions.
...

Sheet Sheet1
A1: Users who Collaborated
A2: 26
A3: 25
A4: 56
A5: 21
A6: 66
A7: 61
A8: 35
A9: 37
A10: 71
A11: 70 | C11: Both | D11: 3.3018868 | E11: 3.2075472 | F11: 3.3846154 | G11: 3.1509434 | H11: 3.4150943 | I11: 3.2264151 | J11: 3.1538462 | K11: 3.245283 | L11: 3.3396226 | M11: 3.5471698
A12: 76 | C12: Collab | D12: 3 | E12: 2.8571429 | F12: 3.1428571 | G12: 2.9285714 | H12: 3.1428571 | I12: 2.9285714 | J12: 3 | K12: 3.0714286 | L12: 3.0714286 | M12: 3.4285714
A13: 69 | C13: Ind | D13: 3.4102564 | E13: 3.3333333 | F13: 3.4736842 | G13: 3.2307692 | H13: 3.5128205 | I13: 3.3333333 | J13: 3.2051282 | K13: 3.3076923 | L13: 3.4358974 | M13: 3.5897436
A14: 7
A15: 34
A16: 77
A17: 67

Sheet Average time collab
A1: 7 | B1: 1003 | C1: 21 | D1: 89 | E1: 25 | F1: 33 | G1: 26 | H1: 423 | I1: 34 | J1: 124 | K1: 35 | L1: 59 | M1: 37 | N1: 427 | O1: 56 | P1: 31 | Q1: 61 | R1: 34 | S1: 66 | T1: 36 | U1: 67 | V1: 231 | W1: 69 | X1: 32 | Y1: 70 | Z1: 141 | AA1: 71 | AB1: 29 | AC1: 76 | AD1: 95 | AE1: 77 | AF1: 25
A2: 7 | B2: 70 | C2: 21 | D2: 29 | E2: 25 | F2: 25 | G2: 26 | H2: 6 | I2: 34 | J2: 13 | K2: 35 | L2: 16 | M2: 37 | N2: 67 | O2: 56 | P2: 108 | Q2: 61 | R2: 81 | S2: 66 | T2: 23 | W2: 69 | X2: 48 | Y2: 70 | Z2: 104 | AA2: 71 | AB2: 67 | AC2: 76 | AD2: 639 | AE2: 77 | AF2: 15
A3: 7 | B3: 26 | C3: 21 | D3: 20 | E3: 25 | F3: 136 | G3: 26 | H3: 38 | I3: 34 | J3: 4 | K3: 35 | L3: 55 | M3: 37 | N3: 355 | O3: 56 | P3: 123 | Q3: 61 | R3: 90 | S3: 66 | T3: 16 | W3: 69 | X3: 136 | Y3: 70 | Z3: 30 | AA3: 71 | AB3: 34 | AC3: 76 | AD3: 54 | AE3: 77 | AF3: 13
A4: 7 | B4: 11 | C4: 21 | D4: 17 | E4: 25 | F4: 114 | G4: 26 | H4: 75 | I4: 34 | J4: 149 | K4: 35 | L4: 23 | M4: 37 | N4: 129 | O4: 56 | P4: 51 | Q4: 61 | R4: 50 | S4: 66 | T4: 40 | W4: 69 | X4: 26 | Y4: 70 | Z4: 65 | AA4: 71 | AB4: 36 | AC4: 76 | AD4: 33 | AE4: 77 | AF4: 15
A5: 7 | B5: 202 | C5: 21 | D5: 60 | E5: 25 | F5: 207 | G5: 26 | H5: 104 | I5: 34 | J5: 26 | K5: 35 | L5: 23 | M5: 37 | N5: 115 | O5: 56 | P5: 125 | Q5: 61 | R5: 35 | S5: 66 | T5: 18 | W5: 69 | X5: 24 | Y5: 70 | Z5: 52 | AA5: 71 | AB5: 24 | AC5: 76 | AD5: 16 | AE5: 77 | AF5: 18
A6: 7 | B6: 83 | C6: 21 | D6: 24 | E6: 25 | F6: 69 | G6: 26 | H6: 123 | K6: 35 | L6: 16 | M6: 37 | N6: 34 | O6: 56 | P6: 57 | Q6: 61 | R6: 34 | S6: 66 | T6: 18 | W6: 69 | X6: 21 | Y6: 70 | Z6: 26 | AA6: 71 | AB6: 26 | AC6: 76 | AD6: 41 | AE6: 77 | AF6: 12
A7: 7 | B7: 375 | C7: 21 | D7: 28 | E7: 25 | F7: 5 | G7: 26 | H7: 160 | K7: 35 | L7: 17 | M7: 37 | N7: 55 | O7: 56 | P7: 28 | Q7: 61 | R7: 30 | S7: 66 | T7: 13 | W7: 69 | X7: 26 | Y7: 70 | Z7: 31 | AA7: 71 | AB7: 18 | AC7: 76 | AD7: 16 | AE7: 77 | AF7: 16
A8: 7 | B8: 164 | C8: 21 | D8: 9 | E8: 25 | F8: 21 | G8: 26 | H8: 32 | K8: 35 | L8: 19 | M8: 37 | N8: 88 | O8: 56 | P8: 50 | Q8: 61 | R8: 28 | S8: 66 | T8: 27 | W8: 69 | X8: 19 | Y8: 70 | Z8: 25 | AA8: 71 | AB8: 19 | AC8: 76 | AD8: 15 | AE8: 77 | AF8: 11
A9: 7 | B9: 73 | C9: 21 | D9: 11 | E9: 25 | F9: 48 | G9: 26 | H9: 30 | K9: 35 | L9: 10 | M9: 37 | N9: 18 | O9: 56 | P9: 65 | Q9: 61 | R9: 81 | S9: 66 | T9: 8 | W9: 69 | X9: 21 | Y9: 70 | Z9: 14 | AA9: 71 | AB9: 15 | AC9: 76 | AD9: 13 | AE9: 77 | AF9: 28
A10: 7 | B10: 72 | C10: 21 | D10: 15 | E10: 25 | F10: 69 | G10: 26 | H10: 30 | K10: 35 | L10: 7 | O10: 56 | P10: 36 | Q10: 61 | R10: 30 | S10: 66 | T10: 10 | W10: 69 | X10: 24 | Y10: 70 | Z10: 16 | AA10: 71 | AB10: 11 | AC10: 76 | AD10: 14 | AE10: 77 | AF10: 6
A11: 7 | B11: 32 | C11: 21 | D11: 10 | E11: 25 | F11: 70 | G11: 26 | H11: 21 | K11: 35 | L11: 7 | O11: 56 | P11: 41 | Q11: 61 | R11: 45 | S11: 66 | T11: 11 | W11: 69 | X11: 9 | Y11: 70 | Z11: 15 | AA11: 71 | AB11: 7 | AC11: 76 | AD11: 10 | AE11: 77 | AF11: 6
A12: 7 | B12: 33 | C12: 21 | D12: 12 | E12: 25 | F12: 25 | G12: 26 | H12: 27 | K12: 35 | L12: 5 | O12: 56 | P12: 39 | Q12: 61 | R12: 43 | S12: 66 | T12: 8 | W12: 69 | X12: 38 | Y12: 70 | Z12: 20 | AA12: 71 | AB12: 117 | AC12: 76 | AD12: 9 | AE12: 77 | AF12: 16
A13: 7 | B13: 44 | C13: 21 | D13: 9 | E13: 25 | F13: 126 | G13: 26 | H13: 20 | K13: 35 | L13: 5 | O13: 56 | P13: 22 | Q13: 61 | R13: 28 | S13: 66 | T13: 12 | W13: 69 | X13: 25 | Y13: 70 | Z13: 7 | AA13: 71 | AB13: 29 | AC13: 76 | AD13: 8 | AE13: 77 | AF13: 22
A14: 7 | B14: 16 | C14: 21 | D14: 16 | E14: 25 | F14: 15 | G14: 26 | H14: 23 | K14: 35 | L14: 5 | O14: 56 | P14: 76 | Q14: 61 | R14: 35 | S14: 66 | T14: 8 | W14: 69 | X14: 37 | Y14: 70 | Z14: 21 | AA14: 71 | AB14: 39 | AC14: 76 | AD14: 20 | AE14: 77 | AF14: 41
A15: 7 | B15: 20 | C15: 21 | D15: 19 | E15: 25 | F15: 59 | G15: 26 | H15: 61 | K15: 35 | L15: 71 | O15: 56 | P15: 57 | Q15: 61 | R15: 37 | S15: 66 | T15: 8 | W15: 69 | X15: 45 | Y15: 70 | Z15: 12 | AA15: 71 | AB15: 26 | AC15: 76 | AD15: 16 | AE15: 77 | AF15: 12
A16: 7 | B16: 15 | C16: 21 | D16: 9 | E16: 25 | F16: 28 | G16: 26 | H16: 14 | K16: 35 | L16: 11 | O16: 56 | P16: 51 | Q16: 61 | R16: 29 | S16: 66 | T16: 11 | W16: 69 | X16: 59 | Y16: 70 | Z16: 13 | AA16: 71 | AB16: 17 | AC16: 76 | AD16: 43 | AE16: 77 | AF16: 11
A17: 7 | B17: 16 | C17: 21 | D17: 31 | E17: 25 | F17: 59 | G17: 26 | H17: 17 | K17: 35 | L17: 31 | O17: 56 | P17: 29 | Q17: 61 | R17: 19 | S17: 66 | T17: 6 | W17: 69 | X17: 50 | Y17: 70 | Z17: 18 | AA17: 71 | AB17: 24 | AC17: 76 | AD17: 21 | AE17: 77 | AF17: 9
A18: 7 | B18: 14 | C18: 21 | D18: 17 | E18: 25 | F18: 88 | G18: 26 | H18: 54 | K18: 35 | L18: 7 | O18: 56 | P18: 47 | Q18: 61 | R18: 193 | S18: 66 | T18: 8 | W18: 69 | X18: 33 | Y18: 70 | Z18: 22 | AA18: 71 | AB18: 682 | AC18: 76 | AD18: 34 | AE18: 77 | AF18: 481
A19: 7 | B19: 47 | C19: 21 | D19: 12 | E19: 25 | F19: 522 | G19: 26 | H19: 71 | K19: 35 | L19: 24 | O19: 56 | P19: 19 | S19: 66 | T19: 14 | W19: 69 | X19: 32 | Y19: 70 | Z19: 15 | AA19: 71 | AB19: 71 | AC19: 76 | AD19: 6 | AE19: 77 | AF19: 62
A20: 7 | B20: 475 | C20: 21 | D20: 115 | G20: 26 | H20: 47 | K20: 35 | L20: 10 | O20: 56 | P20: 20 | S20: 66 | T20: 12 | W20: 69 | X20: 31 | Y20: 70 | Z20: 13 | AA20: 71 | AB20: 128 | AC20: 76 | AD20: 13 | AE20: 77 | AF20: 76
A21: 7 | B21: 199 | C21: 21 | D21: 141 | G21: 26 | H21: 59 | K21: 35 | L21: 23 | O21: 56 | P21: 75 | S21: 66 | T21: 18 | Y21: 70 | Z21: 15 | AA21: 71 | AB21: 77 | AC21: 76 | AD21: 21 | AE21: 77 | AF21: 500
A22: 7 | B22: 206 | C22: 21 | D22: 120 | G22: 26 | H22: 23 | K22: 35 | L22: 14 | O22: 56 | P22: 65 | S22: 66 | T22: 14 | Y22: 70 | Z22: 11 | AA22: 71 | AB22: 76 | AC22: 76 | AD22: 9 | AE22: 77 | AF22: 154
A23: 7 | B23: 225 | C23: 21 | D23: 43 | G23: 26 | H23: 80 | K23: 35 | L23: 7 | O23: 56 | P23: 64 | S23: 66 | T23: 14 | Y23: 70 | Z23: 130 | AA23: 71 | AB23: 92 | AC23: 76 | AD23: 226 | AE23: 77 | AF23: 110
A24: 7 | B24: 14 | C24: 21 | D24: 105 | G24: 26 | H24: 148 | K24: 35 | L24: 65 | O24: 56 | P24: 93 | S24: 66 | T24: 7 | Y24: 70 | Z24: 261 | AC24: 76 | AD24: 64 | AE24: 77 | AF24: 267
A25: 7 | B25: 168 | C25: 21 | D25: 148 | G25: 26 | H25: 54 | K25: 35 | L25: 20 | O25: 56 | P25: 176 | S25: 66 | T25: 15 | Y25: 70 | Z25: 98 | AC25: 76 | AD25: 55 | AE25: 77 | AF25: 158
A26: 7 | B26: 20 | G26: 26 | H26: 21 | K26: 35 | L26: 38 | O26: 56 | P26: 80 | S26: 66 | T26: 12 | Y26: 70 | Z26: 24 | AC26: 76 | AD26: 44 | AE26: 77 | AF26: 36
A27: 7 | B27: 140 | G27: 26 | H27: 21 | K27: 35 | L27: 24 | O27: 56 | P27: 110 | S27: 66 | T27: 33 | Y27: 70 | Z27: 132 | AC27: 76 | AD27: 54 | AE27: 77 | AF27: 43
A28: 7 | B28: 42 | G28: 26 | H28: 53 | K28: 35 | L28: 17 | S28: 66 | T28: 13 | Y28: 70 | Z28: 67 | AC28: 76 | AD28: 131 | AE28: 77 | AF28: 38
A29: 7 | B29: 49 | G29: 26 | H29: 141 | K29: 35 | L29: 22 | S29: 66 | T29: 22 | AC29: 76 | AD29: 64 | AE29: 77 | AF29: 25
A30: 7 | B30: 221 | G30: 26 | H30: 43 | S30: 66 | T30: 57 | AE30: 77 | AF30: 40
A31: 7 | B31: 320 | G31: 26 | H31: 40 | S31: 66 | T31: 35 | AE31: 77 | AF31: 63
A32: 7 | B32: 1583 | G32: 26 | H32: 69 | AE32: 77 | AF32: 152
A33: 7 | B33: 184 | G33: 26 | H33: 35
A34: 7 | B34: 43 | G34: 26 | H34: 23
A35: 7 | B35: 156 | G35: 26 | H35: 178
A36: 7 | B36: 121 | G36: 26 | H36: 74
A37: 7 | B37: 39 | G37: 26 | H37: 94
A38: 7 | B38: 80 | G38: 26 | H38: 101
A39: 7 | B39: 107 | G39: 26 | H39: 87
A40: 7 | B40: 230 | G40: 26 | H40: 102
...

Sheet Average Time
A1: 1 | B1: 61 | C1: 12 | D1: 12 | E1: 11 | F1: 8 | G1: 19 | H1: 61 | I1: 41 | J1: 107 | K1: 29 | L1: 8 | M1: 11
A2: 4 | B2: 53 | C2: 17 | D2: 17 | E2: 33 | F2: 106 | G2: 73 | H2: 67 | I2: 7 | J2: 15 | K2: 11 | L2: 15 | M2: 26 | N2: 12 | O2: 8 | P2: 41 | Q2: 6 | R2: 6 | S2: 16 | T2: 12 | U2: 7 | V2: 42 | W2: 9 | X2: 19 | Y2: 9 | Z2: 16 | AA2: 8 | AB2: 24 | AC2: 8 | AD2: 9 | AE2: 291 | AF2: 66 | AG2: 14 | AH2: 32 | AI2: 92 | AJ2: 39 | AK2: 51 | AL2: 62
A3: 5 | B3: 61 | C3: 61 | D3: 61 | E3: 61 | F3: 61 | G3: 61 | H3: 61 | I3: 61 | J3: 61 | K3: 61 | L3: 61 | M3: 61 | N3: 61 | O3: 61 | P3: 61 | Q3: 61 | R3: 61
A4: 6 | B4: 61 | C4: 61 | D4: 61 | E4: 61 | F4: 61 | G4: 61 | H4: 61 | I4: 61 | J4: 61 | K4: 61 | L4: 61 | M4: 61 | N4: 61 | O4: 61 | P4: 61 | Q4: 61 | R4: 61 | S4: 61 | T4: 61 | U4: 61 | V4: 61 | W4: 61 | X4: 61 | Y4: 61 | Z4: 61 | AA4: 61 | AB4: 61 | AC4: 61 | AD4: 61 | AE4: 61 | AF4: 61 | AG4: 61 | AH4: 61 | AI4: 61 | AJ4: 61 | AK4: 61 | AL4: 61 | AM4: 61 | AN4: 61 | AO4: 61 | AP4: 61 | AQ4: 61 | AR4: 61 | AS4: 61 | AT4: 61 | AU4: 61 | AV4: 61
A5: 8 | B5: 69 | C5: 34 | D5: 83 | E5: 87 | F5: 13 | G5: 28 | H5: 28 | I5: 17 | J5: 47 | K5: 24 | L5: 19 | M5: 12 | N5: 24 | O5: 11 | P5: 11 | Q5: 45 | R5: 33 | S5: 13 | T5: 19 | U5: 13 | V5: 6 | W5: 244 | X5: 93 | Y5: 203 | Z5: 48 | AA5: 87
A6: 11 | B6: 61 | C6: 61 | D6: 61 | E6: 61 | F6: 61 | G6: 61 | H6: 61 | I6: 61 | J6: 61 | K6: 61 | L6: 61 | M6: 61 | N6: 61 | O6: 61 | P6: 61 | Q6: 61 | R6: 61 | S6: 61 | T6: 61 | U6: 61 | V6: 61 | W6: 61 | X6: 61 | Y6: 61 | Z6: 61 | AA6: 61 | AB6: 61 | AC6: 61 | AD6: 61 | AE6: 61
A7: 12 | B7: 61 | C7: 61 | D7: 61 | E7: 61 | F7: 61 | G7: 61 | H7: 61 | I7: 61 | J7: 61 | K7: 61 | L7: 61 | M7: 61 | N7: 61 | O7: 61 | P7: 61 | Q7: 61 | R7: 61 | S7: 61 | T7: 61 | U7: 61 | V7: 61 | W7: 61 | X7: 61 | Y7: 61 | Z7: 65 | AA7: 16 | AB7: 25 | AC7: 25 | AD7: 7 | AE7: 39 | AF7: 16 | AG7: 19 | AH7: 17 | AI7: 142 | AJ7: 69 | AK7: 77 | AL7: 582 | AM7: 70 | AN7: 53
A8: 13 | B8: 61 | C8: 61 | D8: 61 | E8: 61 | F8: 61 | G8: 61 | H8: 61 | I8: 61 | J8: 61 | K8: 61 | L8: 61 | M8: 61 | N8: 61 | O8: 61 | P8: 61 | Q8: 61 | R8: 61 | S8: 61 | T8: 61 | U8: 61 | V8: 61 | W8: 61 | X8: 61 | Y8: 61 | Z8: 61 | AA8: 61 | AB8: 61 | AC8: 61 | AD8: 61
A9: 14 | B9: 15 | C9: 27 | D9: 21 | E9: 21 | F9: 65 | G9: 20 | H9: 24 | I9: 59 | J9: 71 | K9: 183 | L9: 65 | M9: 42 | N9: 31 | O9: 92 | P9: 70 | Q9: 19 | R9: 16 | S9: 37 | T9: 37 | U9: 47 | V9: 36 | W9: 14 | X9: 51 | Y9: 20 | Z9: 16 | AA9: 11 | AB9: 7 | AC9: 10 | AD9: 13 | AE9: 6 | AF9: 5 | AG9: 18 | AH9: 26 | AI9: 62 | AJ9: 115 | AK9: 59 | AL9: 266 | AM9: 154 | AN9: 7 | AO9: 11 | AP9: 38 | AQ9: 3 | AR9: 17 | AS9: 6 | AT9: 15 | AU9: 9 | AV9: 1090 | AW9: 155 | AX9: 353 | AY9: 1809 | AZ9: 211 | BA9: 147 | BB9: 245 | BC9: 26 | BD9: 48 | BE9: 48 | BF9: 35 | BG9: 48
A10: 15 | B10: 61 | C10: 61 | D10: 61 | E10: 61 | F10: 61 | G10: 61 | H10: 61 | I10: 61 | J10: 61 | K10: 61 | L10: 61 | M10: 61 | N10: 61 | O10: 61 | P10: 61 | Q10: 61 | R10: 61 | S10: 61 | T10: 61 | U10: 61 | V10: 61 | W10: 61 | X10: 61 | Y10: 61 | Z10: 61 | AA10: 61 | AB10: 61 | AC10: 61 | AD10: 61 | AE10: 61 | AF10: 61 | AG10: 61 | AH10: 61 | AI10: 61 | AJ10: 61 | AK10: 61 | AL10: 61 | AM10: 61 | AN10: 61 | AO10: 61 | AP10: 61
A11: 16 | B11: 61 | C11: 61 | D11: 61 | E11: 61 | F11: 61 | G11: 61 | H11: 61 | I11: 61 | J11: 61 | K11: 61 | L11: 61 | M11: 61 | N11: 61 | O11: 61 | P11: 61 | Q11: 61 | R11: 61 | S11: 61 | T11: 61 | U11: 61 | V11: 61 | W11: 61 | X11: 61 | Y11: 61 | Z11: 61 | AA11: 61 | AB11: 61 | AC11: 61 | AD11: 61 | AE11: 61 | AF11: 61 | AG11: 61 | AH11: 61 | AI11: 61 | AJ11: 61 | AK11: 61 | AL11: 61 | AM11: 61 | AN11: 61 | AO11: 61 | AP11: 61 | AQ11: 61 | AR11: 61 | AS11: 61 | AT11: 61 | AU11: 61 | AV11: 61 | AW11: 61 | AX11: 61 | AY11: 61 | AZ11: 61 | BA11: 61 | BB11: 61 | BC11: 61 | BD11: 61 | BE11: 61 | BF11: 21 | BG11: 23
A12: 17 | B12: 91 | C12: 18 | D12: 17 | E12: 40 | F12: 42 | G12: 47 | H12: 15 | I12: 38 | J12: 17 | K12: 22 | L12: 21 | M12: 9 | N12: 6 | O12: 8 | P12: 7 | Q12: 6 | R12: 5 | S12: 23 | T12: 11 | U12: 37 | V12: 54 | W12: 28 | X12: 23 | Y12: 31 | Z12: 11 | AA12: 28 | AB12: 4 | AC12: 11 | AD12: 16 | AE12: 11 | AF12: 11 | AG12: 12 | AH12: 6 | AI12: 1618 | AJ12: 10 | AK12: 44 | AL12: 64 | AM12: 69 | AN12: 40 | AO12: 104 | AP12: 61 | AQ12: 108
A13: 19 | B13: 19 | C13: 25 | D13: 44 | E13: 25 | F13: 33 | G13: 78 | H13: 12 | I13: 16 | J13: 13 | K13: 59 | L13: 8 | M13: 6 | N13: 174 | O13: 26 | P13: 16 | Q13: 13 | R13: 59 | S13: 10 | T13: 12 | U13: 26 | V13: 8
A14: 20 | B14: 75 | C14: 14 | D14: 10 | E14: 13 | F14: 21 | G14: 13 | H14: 10 | I14: 13 | J14: 10 | K14: 11 | L14: 6 | M14: 6 | N14: 5 | O14: 97 | P14: 38 | Q14: 9 | R14: 16 | S14: 11 | T14: 16 | U14: 15 | V14: 9 | W14: 6 | X14: 184 | Y14: 18 | Z14: 23 | AA14: 49 | AB14: 47 | AC14: 53 | AD14: 63
A15: 22 | B15: 187 | C15: 29 | D15: 36 | E15: 61 | F15: 17 | G15: 16 | H15: 81 | I15: 43 | J15: 11 | K15: 10 | L15: 22 | M15: 11 | N15: 12 | O15: 14 | P15: 26 | Q15: 10 | R15: 16 | S15: 15 | T15: 74 | U15: 287 | V15: 532 | W15: 17 | X15: 46 | Y15: 130 | Z15: 71 | AA15: 218 | AB15: 67 | AC15: 160 | AD15: 22 | AE15: 32 | AF15: 9 | AG15: 13 | AH15: 7 | AI15: 12 | AJ15: 9 | AK15: 126 | AL15: 477 | AM15: 123 | AN15: 177 | AO15: 90 | AP15: 114 | AQ15: 78 | AR15: 11 | AS15: 15
A16: 23 | B16: 269 | C16: 34 | D16: 29 | E16: 31 | F16: 39 | G16: 25 | H16: 15 | I16: 16 | J16: 28 | K16: 11 | L16: 8 | M16: 7 | N16: 83 | O16: 36 | P16: 22 | Q16: 15 | R16: 60 | S16: 14 | T16: 17 | U16: 13 | V16: 18 | W16: 28 | X16: 11 | Y16: 10 | Z16: 6 | AA16: 123 | AB16: 158 | AC16: 6 | AD16: 6 | AE16: 103 | AF16: 40 | AG16: 99 | AH16: 4 | AI16: 277 | AJ16: 12
A17: 24 | B17: 66 | C17: 65 | D17: 39 | E17: 53 | F17: 24 | G17: 22 | H17: 20 | I17: 17 | J17: 21 | K17: 10 | L17: 15 | M17: 6 | N17: 6 | O17: 32 | P17: 47 | Q17: 68 | R17: 61 | S17: 81 | T17: 201 | U17: 5 | V17: 9 | W17: 34 | X17: 67 | Y17: 62 | Z17: 31 | AA17: 11 | AB17: 16 | AC17: 9 | AD17: 8 | AE17: 26 | AF17: 169 | AG17: 38
A18: 27 | B18: 152 | C18: 127 | D18: 82 | E18: 186 | F18: 27 | G18: 16 | H18: 216 | I18: 59 | J18: 10 | K18: 135 | L18: 83 | M18: 111 | N18: 192 | O18: 88 | P18: 53 | Q18: 29 | R18: 21 | S18: 39 | T18: 124 | U18: 52 | V18: 17 | W18: 121 | X18: 104 | Y18: 47 | Z18: 12 | AA18: 14 | AB18: 14 | AC18: 63 | AD18: 9 | AE18: 57
A19: 28 | B19: 29
A20: 30 | B20: 19 | C20: 20 | D20: 13 | E20: 36 | F20: 19 | G20: 11 | H20: 8 | I20: 70 | J20: 18 | K20: 10 | L20: 17 | M20: 6 | N20: 9 | O20: 7 | P20: 5 | Q20: 5 | R20: 8 | S20: 26 | T20: 52 | U20: 21 | V20: 8 | W20: 8 | X20: 16 | Y20: 16 | Z20: 4 | AA20: 10 | AB20: 5 | AC20: 6 | AD20: 5 | AE20: 50 | AF20: 49 | AG20: 48 | AH20: 20 | AI20: 34 | AJ20: 56 | AK20: 22 | AL20: 36 | AM20: 82
A21: 32 | B21: 20 | C21: 10 | D21: 11 | E21: 29 | F21: 72 | G21: 40 | H21: 26 | I21: 25 | J21: 27 | K21: 18 | L21: 19 | M21: 17 | N21: 18 | O21: 27 | P21: 29 | Q21: 16 | R21: 33 | S21: 24 | T21: 13 | U21: 14 | V21: 11 | W21: 13 | X21: 9 | Y21: 72 | Z21: 26 | AA21: 46
A22: 33 | B22: 12 | C22: 21 | D22: 12 | E22: 41 | F22: 52 | G22: 22 | H22: 15 | I22: 38 | J22: 22 | K22: 85 | L22: 28 | M22: 75 | N22: 18 | O22: 6 | P22: 19 | Q22: 14 | R22: 15 | S22: 81 | T22: 28 | U22: 78 | V22: 40 | W22: 30 | X22: 121 | Y22: 16 | Z22: 17 | AA22: 22 | AB22: 14 | AC22: 16 | AD22: 12 | AE22: 11 | AF22: 16 | AG22: 8 | AH22: 10 | AI22: 9 | AJ22: 11 | AK22: 15 | AL22: 14 | AM22: 17 | AN22: 14 | AO22: 14 | AP22: 282 | AQ22: 17 | AR22: 28 | AS22: 14 | AT22: 69 | AU22: 45 | AV22: 79 | AW22: 207 | AX22: 19 | AY22: 9 | AZ22: 35 | BA22: 23 | BB22: 32 | BC22: 287 | BD22: 149 | BE22: 32 | BF22: 49 | BG22: 39 | BH22: 26 | BI22: 20 | BJ22: 9 | BK22: 14 | BL22: 157 | BM22: 25 | BN22: 87 | BO22: 20 | BP22: 12 | BQ22: 14 | BR22: 35 | BS22: 28 | BT22: 35 | BU22: 124 | BV22: 23 | BW22: 70 | BX22: 18 | BY22: 128 | BZ22: 30 | CA22: 88 | CB22: 39 | CC22: 38 | CD22: 32 | CE22: 140 | CF22: 55 | CG22: 18
A23: 36 | B23: 131 | C23: 84 | D23: 55 | E23: 43 | F23: 51 | G23: 44 | H23: 19 | I23: 30 | J23: 15 | K23: 17 | L23: 15 | M23: 16 | N23: 13 | O23: 20 | P23: 23 | Q23: 25 | R23: 19 | S23: 12 | T23: 13 | U23: 16 | V23: 9 | W23: 329 | X23: 105 | Y23: 47 | Z23: 72
A24: 38 | B24: 174 | C24: 31 | D24: 48 | E24: 72 | F24: 26 | G24: 28 | H24: 82 | I24: 36 | J24: 57 | K24: 18 | L24: 15 | M24: 11 | N24: 16 | O24: 157 | P24: 15 | Q24: 159 | R24: 217 | S24: 199 | T24: 21 | U24: 28 | V24: 54 | W24: 21 | X24: 86 | Y24: 14 | Z24: 39 | AA24: 14 | AB24: 15 | AC24: 6 | AD24: 667 | AE24: 187 | AF24: 49 | AG24: 150 | AH24: 200 | AI24: 45 | AJ24: 79 | AK24: 73 | AL24: 137 | AM24: 89
A25: 42 | B25: 110 | C25: 118 | D25: 31 | E25: 26 | F25: 43 | G25: 40 | H25: 89 | I25: 33 | J25: 17 | K25: 12 | L25: 22 | M25: 29 | N25: 9 | O25: 9 | P25: 8 | Q25: 8 | R25: 21 | S25: 14 | T25: 26 | U25: 15 | V25: 32 | W25: 7 | X25: 6 | Y25: 36 | Z25: 32 | AA25: 15 | AB25: 21 | AC25: 12 | AD25: 23 | AE25: 9 | AF25: 11 | AG25: 150 | AH25: 151 | AI25: 152 | AJ25: 106 | AK25: 136 | AL25: 536
A26: 43 | B26: 133 | C26: 23 | D26: 62 | E26: 21 | F26: 48 | G26: 46 | H26: 22 | I26: 19 | J26: 13 | K26: 14 | L26: 12 | M26: 9 | N26: 14 | O26: 9 | P26: 9 | Q26: 22 | R26: 37 | S26: 70 | T26: 15 | U26: 12 | V26: 84 | W26: 11 | X26: 10 | Y26: 13 | Z26: 11 | AA26: 566 | AB26: 56 | AC26: 158 | AD26: 39 | AE26: 140 | AF26: 115 | AG26: 63 | AH26: 87 | AI26: 58 | AJ26: 55
A27: 45 | B27: 80 | C27: 25 | D27: 53 | E27: 29 | F27: 46 | G27: 251 | H27: 42 | I27: 17 | J27: 10 | K27: 8 | L27: 14 | M27: 10 | N27: 14 | O27: 9 | P27: 15 | Q27: 44 | R27: 17 | S27: 12 | T27: 9 | U27: 17 | V27: 8 | W27: 117 | X27: 27 | Y27: 258
A28: 47 | B28: 59 | C28: 33 | D28: 24 | E28: 20 | F28: 25 | G28: 108 | H28: 16 | I28: 34 | J28: 21 | K28: 10 | L28: 13 | M28: 22 | N28: 8 | O28: 12 | P28: 15 | Q28: 8 | R28: 12 | S28: 54 | T28: 11 | U28: 45 | V28: 30 | W28: 35 | X28: 12 | Y28: 24 | Z28: 12 | AA28: 10 | AB28: 229 | AC28: 92 | AD28: 91 | AE28: 172
A29: 48 | B29: 76 | C29: 70 | D29: 70 | E29: 36 | F29: 27 | G29: 36 | H29: 18 | I29: 18 | J29: 18 | K29: 15 | L29: 11 | M29: 6 | N29: 11 | O29: 19 | P29: 25 | Q29: 13 | R29: 11 | S29: 13 | T29: 9 | U29: 310 | V29: 211 | W29: 72 | X29: 90 | Y29: 88 | Z29: 45 | AA29: 103 | AB29: 126 | AC29: 548 | AD29: 47 | AE29: 57
A30: 49 | B30: 48 | C30: 70 | D30: 20 | E30: 29 | F30: 39 | G30: 63 | H30: 16 | I30: 27 | J30: 10 | K30: 10 | L30: 6 | M30: 8 | N30: 92 | O30: 10 | P30: 10 | Q30: 26 | R30: 6 | S30: 15 | T30: 15 | U30: 6 | V30: 8 | W30: 12 | X30: 6 | Y30: 530 | Z30: 131 | AA30: 188 | AB30: 32 | AC30: 30 | AD30: 98 | AE30: 675 | AF30: 51 | AG30: 29
A31: 52 | B31: 274 | C31: 22 | D31: 27 | E31: 360 | F31: 124 | G31: 247 | H31: 151 | I31: 422 | J31: 56 | K31: 52 | L31: 22 | M31: 13 | N31: 14 | O31: 14 | P31: 18 | Q31: 8 | R31: 6 | S31: 32 | T31: 436 | U31: 77 | V31: 4 | W31: 674 | X31: 23 | Y31: 40 | Z31: 11 | AA31: 10 | AB31: 12 | AC31: 11 | AD31: 10 | AE31: 256 | AF31: 56 | AG31: 74 | AH31: 56 | AI31: 54 | AJ31: 43
A32: 54 | B32: 574 | C32: 44 | D32: 21 | E32: 72 | F32: 96 | G32: 3 | H32: 12 | I32: 21 | J32: 32 | K32: 65 | L32: 44 | M32: 50 | N32: 204 | O32: 15 | P32: 54 | Q32: 43 | R32: 68 | S32: 37 | T32: 12 | U32: 15 | V32: 13 | W32: 8 | X32: 59 | Y32: 7 | Z32: 44 | AA32: 5 | AB32: 43 | AC32: 12 | AD32: 71 | AE32: 46 | AF32: 14 | AG32: 21 | AH32: 11 | AI32: 15 | AJ32: 40 | AK32: 17 | AL32: 19 | AM32: 51 | AN32: 10 | AO32: 7 | AP32: 544 | AQ32: 6 | AR32: 30 | AS32: 6 | AT32: 7 | AU32: 36 | AV32: 73 | AW32: 36 | AX32: 36 | AY32: 86 | AZ32: 35 | BA32: 241 | BB32: 136 | BC32: 24 | BD32: 32 | BE32: 63 | BF32: 77 | BG32: 98 | BH32: 47 | BI32: 40 | BJ32: 92 | BK32: 155 | BL32: 4 | BM32: 46 | BN32: 20 | BO32: 52 | BP32: 94 | BQ32: 4 | BR32: 24 | BS32: 5 | BT32: 11 | BU32: 3 | BV32: 4 | BW32: 55 | BX32: 3 | BY32: 183 | BZ32: 494
A33: 55 | B33: 293 | C33: 38 | D33: 24 | E33: 18 | F33: 40 | G33: 19 | H33: 13 | I33: 11 | J33: 10 | K33: 10 | L33: 9 | M33: 7 | N33: 8 | O33: 7 | P33: 5 | Q33: 12 | R33: 8 | S33: 14 | T33: 12 | U33: 12 | V33: 12 | W33: 11 | X33: 67 | Y33: 88 | Z33: 31 | AA33: 89 | AB33: 32 | AC33: 33 | AD33: 35 | AE33: 137 | AF33: 78 | AG33: 189 | AH33: 144 | AI33: 60 | AJ33: 103 | AK33: 79
A34: 57 | B34: 674 | C34: 30 | D34: 25 | E34: 27 | F34: 57 | G34: 30 | H34: 13 | I34: 32 | J34: 12 | K34: 13 | L34: 11 | M34: 154 | N34: 63 | O34: 78 | P34: 87 | Q34: 457 | R34: 74 | S34: 21 | T34: 10 | U34: 24 | V34: 20 | W34: 12 | X34: 18 | Y34: 17 | Z34: 17 | AA34: 94 | AB34: 23 | AC34: 31 | AD34: 14 | AE34: 10 | AF34: 444 | AG34: 35 | AH34: 195 | AI34: 203 | AJ34: 119 | AK34: 396
A35: 58 | B35: 46 | C35: 50 | D35: 31 | E35: 35 | F35: 35 | G35: 21 | H35: 26 | I35: 26 | J35: 25 | K35: 18 | L35: 20 | M35: 8 | N35: 7 | O35: 71 | P35: 55 | Q35: 27 | R35: 18 | S35: 198 | T35: 29 | U35: 28 | V35: 16 | W35: 13 | X35: 11 | Y35: 251 | Z35: 182 | AA35: 69 | AB35: 54 | AC35: 1659 | AD35: 78 | AE35: 80
A36: 62 | B36: 30 | C36: 22 | D36: 125 | E36: 32 | F36: 22 | G36: 37 | H36: 95 | I36: 28 | J36: 210 | K36: 23 | L36: 31 | M36: 11 | N36: 16 | O36: 21 | P36: 30 | Q36: 26 | R36: 35 | S36: 82 | T36: 17 | U36: 29 | V36: 23 | W36: 13 | X36: 13 | Y36: 102 | Z36: 67 | AA36: 116 | AB36: 24 | AC36: 35 | AD36: 18 | AE36: 27 | AF36: 21 | AG36: 146 | AH36: 65 | AI36: 43 | AJ36: 28 | AK36: 101 | AL36: 44 | AM36: 132 | AN36: 35 | AO36: 36 | AP36: 33 | AQ36: 61 | AR36: 33 | AS36: 38 | AT36: 40 | AU36: 124 | AV36: 53 | AW36: 14 | AX36: 25 | AY36: 17 | AZ36: 15 | BA36: 18 | BB36: 25 | BC36: 12 | BD36: 11 | BE36: 96 | BF36: 16 | BG36: 43 | BH36: 10 | BI36: 11
A37: 63 | B37: 42 | C37: 105 | D37: 23 | E37: 60 | F37: 24 | G37: 21 | H37: 23 | I37: 10 | J37: 14 | K37: 8 | L37: 7 | M37: 6 | N37: 5 | O37: 6 | P37: 16 | Q37: 16 | R37: 8 | S37: 8 | T37: 10 | U37: 7 | V37: 74 | W37: 11 | X37: 141 | Y37: 8
A38: 64 | B38: 116 | C38: 63 | D38: 27 | E38: 11 | F38: 21 | G38: 16 | H38: 28 | I38: 42 | J38: 50 | K38: 26 | L38: 12 | M38: 18 | N38: 52 | O38: 18 | P38: 24 | Q38: 40 | R38: 29 | S38: 8 | T38: 20 | U38: 15 | V38: 6 | W38: 6 | X38: 10 | Y38: 9 | Z38: 51 | AA38: 50 | AB38: 39 | AC38: 13 | AD38: 9 | AE38: 17 | AF38: 9 | AG38: 12 | AH38: 9 | AI38: 60 | AJ38: 10 | AK38: 12 | AL38: 12 | AM38: 67 | AN38: 16 | AO38: 20 | AP38: 28 | AQ38: 19 | AR38: 9 | AS38: 97 | AT38: 306 | AU38: 62 | AV38: 32
A39: 65 | B39: 32 | C39: 19 | D39: 15 | E39: 25 | F39: 44 | G39: 12 | H39: 9 | I39: 25 | J39: 14 | K39: 15 | L39: 10 | M39: 9 | N39: 8 | O39: 14 | P39: 20 | Q39: 9 | R39: 11 | S39: 12 | T39: 8 | U39: 555 | V39: 23
A40: 68 | B40: 126 | C40: 66 | D40: 205 | E40: 195 | F40: 17 | G40: 128 | H40: 24 | I40: 12 | J40: 10 | K40: 8 | L40: 8 | M40: 106 | N40: 6 | O40: 132 | P40: 32 | Q40: 80 | R40: 24 | S40: 340 | T40: 20 | U40: 8 | V40: 14 | W40: 9 | X40: 1975 | Y40: 70 | Z40: 267 | AA40: 82 | AB40: 201
...

Sheet Average Time Collab Correct
A1: 7 | B1: 1003 | C1: 21 | D1: 89 | E1: 25 | F1: 33 | G1: 26 | H1: 423 | I1: 34 | J1: 124 | K1: 35 | L1: 16 | M1: 37 | N1: 427 | O1: 56 | P1: 31 | Q1: 61 | R1: 34 | S1: 66 | T1: 36 | U1: 67 | V1: 231 | W1: 69 | X1: 32 | Y1: 70 | Z1: 141 | AA1: 71 | AB1: 29 | AC1: 76 | AD1: 95 | AE1: 77 | AF1: 25
A2: 7 | B2: 70 | C2: 21 | D2: 29 | E2: 25 | F2: 25 | G2: 26 | H2: 38 | I2: 34 | J2: 13 | K2: 35 | L2: 23 | M2: 37 | N2: 67 | O2: 56 | P2: 108 | Q2: 61 | R2: 81 | S2: 66 | T2: 23 | W2: 69 | X2: 48 | Y2: 70 | Z2: 104 | AA2: 71 | AB2: 67 | AC2: 76 | AD2: 639 | AE2: 77 | AF2: 15
A3: 7 | B3: 26 | C3: 21 | D3: 20 | E3: 25 | F3: 126 | G3: 26 | H3: 104 | I3: 34 | J3: 4 | K3: 35 | L3: 23 | M3: 37 | N3: 18 | O3: 56 | P3: 123 | Q3: 61 | R3: 90 | S3: 66 | T3: 40 | W3: 69 | X3: 136 | Y3: 70 | Z3: 30 | AA3: 71 | AB3: 34 | AC3: 76 | AD3: 54 | AE3: 77 | AF3: 13
A4: 7 | B4: 11 | C4: 21 | D4: 17 | E4: 25 | F4: 28 | G4: 26 | H4: 123 | I4: 34 | J4: 149 | K4: 35 | L4: 16 | O4: 56 | P4: 51 | Q4: 61 | R4: 50 | S4: 66 | T4: 18 | W4: 69 | X4: 26 | Y4: 70 | Z4: 65 | AA4: 71 | AB4: 36 | AC4: 76 | AD4: 33 | AE4: 77 | AF4: 15
A5: 7 | B5: 164 | C5: 21 | D5: 24 | E5: 25 | F5: 522 | G5: 26 | H5: 32 | I5: 34 | J5: 26 | K5: 35 | L5: 17 | O5: 56 | P5: 125 | Q5: 61 | R5: 35 | S5: 66 | T5: 8 | W5: 69 | X5: 24 | Y5: 70 | Z5: 52 | AA5: 71 | AB5: 24 | AC5: 76 | AD5: 16 | AE5: 77 | AF5: 18
A6: 7 | B6: 72 | C6: 21 | D6: 28 | F6: 522 | G6: 26 | H6: 30 | K6: 35 | L6: 19 | O6: 56 | P6: 57 | Q6: 61 | R6: 34 | S6: 66 | T6: 10 | W6: 69 | X6: 21 | Y6: 70 | Z6: 26 | AA6: 71 | AB6: 26 | AC6: 76 | AD6: 41 | AE6: 77 | AF6: 12
A7: 7 | B7: 44 | C7: 21 | D7: 9 | G7: 26 | H7: 30 | K7: 35 | L7: 10 | O7: 56 | P7: 50 | Q7: 61 | R7: 30 | S7: 66 | T7: 11 | W7: 69 | X7: 26 | Y7: 70 | Z7: 31 | AA7: 71 | AB7: 18 | AC7: 76 | AD7: 16 | AE7: 77 | AF7: 16
A8: 7 | B8: 16 | C8: 21 | D8: 11 | G8: 26 | H8: 21 | K8: 35 | L8: 7 | O8: 56 | P8: 65 | Q8: 61 | R8: 28 | S8: 66 | T8: 8 | W8: 69 | X8: 19 | Y8: 70 | Z8: 25 | AA8: 71 | AB8: 19 | AC8: 76 | AD8: 15 | AE8: 77 | AF8: 11
A9: 7 | B9: 20 | C9: 21 | D9: 15 | G9: 26 | H9: 27 | K9: 35 | L9: 7 | O9: 56 | P9: 36 | Q9: 61 | R9: 81 | S9: 66 | T9: 12 | W9: 69 | X9: 21 | Y9: 70 | Z9: 15 | AA9: 71 | AB9: 15 | AC9: 76 | AD9: 13 | AE9: 77 | AF9: 28
A10: 7 | B10: 15 | C10: 21 | D10: 10 | G10: 26 | H10: 20 | K10: 35 | L10: 5 | O10: 56 | P10: 41 | Q10: 61 | R10: 30 | S10: 66 | T10: 8 | W10: 69 | X10: 24 | Y10: 70 | Z10: 7 | AA10: 71 | AB10: 11 | AC10: 76 | AD10: 14 | AE10: 77 | AF10: 6
A11: 7 | B11: 16 | C11: 21 | D11: 12 | G11: 26 | H11: 23 | K11: 35 | L11: 5 | O11: 56 | P11: 22 | Q11: 61 | R11: 45 | S11: 66 | T11: 8 | W11: 69 | X11: 9 | Y11: 70 | Z11: 21 | AA11: 71 | AB11: 7 | AC11: 76 | AD11: 10 | AE11: 77 | AF11: 6
A12: 7 | B12: 14 | C12: 21 | D12: 9 | G12: 26 | H12: 17 | K12: 35 | L12: 5 | O12: 56 | P12: 76 | Q12: 61 | R12: 43 | S12: 66 | T12: 12 | W12: 69 | X12: 38 | Y12: 70 | Z12: 12 | AA12: 71 | AB12: 117 | AC12: 76 | AD12: 9 | AE12: 77 | AF12: 16
A13: 7 | B13: 206 | C13: 21 | D13: 16 | G13: 26 | H13: 54 | K13: 35 | L13: 7 | O13: 56 | P13: 57 | Q13: 61 | R13: 28 | S13: 66 | T13: 14 | W13: 69 | X13: 25 | Y13: 70 | Z13: 13 | AA13: 71 | AB13: 29 | AC13: 76 | AD13: 8 | AE13: 77 | AF13: 22
A14: 7 | B14: 20 | C14: 21 | D14: 19 | G14: 26 | H14: 71 | K14: 35 | L14: 24 | O14: 56 | P14: 51 | Q14: 61 | R14: 35 | S14: 66 | T14: 14 | W14: 69 | X14: 50 | Y14: 70 | Z14: 18 | AA14: 71 | AB14: 39 | AC14: 76 | AD14: 21 | AE14: 77 | AF14: 41
A15: 7 | B15: 140 | C15: 21 | D15: 9 | G15: 26 | H15: 47 | K15: 35 | L15: 10 | O15: 56 | P15: 29 | Q15: 61 | R15: 37 | S15: 66 | T15: 7 | W15: 69 | X15: 33 | Y15: 70 | Z15: 22 | AA15: 71 | AB15: 26 | AC15: 76 | AD15: 34 | AE15: 77 | AF15: 12
A16: 7 | B16: 42 | C16: 21 | D16: 31 | G16: 26 | H16: 59 | K16: 35 | L16: 23 | O16: 56 | P16: 47 | Q16: 61 | R16: 29 | S16: 66 | T16: 12 | W16: 69 | X16: 32 | Y16: 70 | Z16: 15 | AA16: 71 | AB16: 17 | AC16: 76 | AD16: 6 | AE16: 77 | AF16: 11
A17: 7 | B17: 1583 | C17: 21 | D17: 17 | G17: 26 | H17: 23 | K17: 35 | L17: 14 | O17: 56 | P17: 19 | Q17: 61 | R17: 19 | S17: 66 | T17: 33 | W17: 69 | X17: 31 | Y17: 70 | Z17: 13 | AA17: 71 | AB17: 24 | AC17: 76 | AD17: 13 | AE17: 77 | AF17: 9
A18: 7 | B18: 156 | C18: 21 | D18: 12 | G18: 26 | H18: 80 | K18: 35 | L18: 7 | O18: 56 | P18: 20 | Q18: 61 | R18: 193 | S18: 66 | T18: 13 | Y18: 70 | Z18: 15 | AA18: 71 | AB18: 682 | AC18: 76 | AD18: 21 | AE18: 77 | AF18: 481
A19: 7 | B19: 790 | C19: 21 | D19: 115 | G19: 26 | H19: 141 | K19: 35 | L19: 65 | O19: 56 | P19: 75 | S19: 66 | T19: 22 | Y19: 70 | Z19: 11 | AA19: 71 | AB19: 71 | AC19: 76 | AD19: 9 | AE19: 77 | AF19: 152
C20: 21 | D20: 43 | G20: 26 | H20: 43 | K20: 35 | L20: 20 | O20: 56 | P20: 65 | S20: 66 | T20: 35 | Y20: 70 | Z20: 98 | AA20: 71 | AB20: 128 | AC20: 76 | AD20: 64
G21: 26 | H21: 74 | K21: 35 | L21: 38 | O21: 56 | P21: 64 | Y21: 70 | Z21: 24 | AA21: 71 | AB21: 77 | AC21: 76 | AD21: 64
G22: 26 | H22: 58 | K22: 35 | L22: 24 | O22: 56 | P22: 176 | Y22: 70 | Z22: 67 | AA22: 71 | AB22: 76
G23: 26 | H23: 40 | K23: 35 | L23: 17 | O23: 56 | P23: 80 | AA23: 71 | AB23: 92
K24: 35 | L24: 22 | O24: 56 | P24: 110
A26: Average Time per Question
A27: =AVERAGE(B1,D1,F1,H1,J1,L1,N1,P1,R1,T1,V1,X1,Z1,AB1,AD1,AF1) -> 173.0625 | C27: =264/16 -> 16.5 | D27: =AVERAGE(A27:A38) -> 53.514198
A28: =AVERAGE(B2,D2,F2,H2,J2,L2,N2,P2,R2,T2,V2,X2,Z2,AB2,AD2,AF2) -> 90
A29: =AVERAGE(B3,D3,F3,H3,J3,L3,N3,P3,R3,T3,V3,X3,Z3,AB3,AD3,AF3) -> 56.066667
A30: =AVERAGE(B4,D4,F4,H4,J4,L4,N4,P4,R4,T4,V4,X4,Z4,AB4,AD4,AF4) -> 45.571429
A31: =AVERAGE(B5,D5,F5,H5,J5,L5,N5,P5,R5,T5,V5,X5,Z5,AB5,AD5,AF5) -> 77.642857
A32: =AVERAGE(B6,D6,F6,H6,J6,L6,N6,P6,R6,T6,V6,X6,Z6,AB6,AD6,AF6) -> 69.076923
A33: =AVERAGE(B7,D7,F7,H7,J7,L7,N7,P7,R7,T7,V7,X7,Z7,AB7,AD7,AF7) -> 24.25
A34: =AVERAGE(B8,D8,F8,H8,J8,L8,N8,P8,R8,T8,V8,X8,Z8,AB8,AD8,AF8) -> 20.416667
A35: =AVERAGE(B9,D9,F9,H9,J9,L9,N9,P9,R9,T9,V9,X9,Z9,AB9,AD9,AF9) -> 24.166667
A36: =AVERAGE(B10,D10,F10,H10,J10,L10,N10,P10,R10,T10,V10,X10,Z10,AB10,AD10,AF10) -> 15.916667
A37: =AVERAGE(B11,D11,F11,H11,J11,L11,N11,P11,R11,T11,V11,X11,Z11,AB11,AD11,AF11) -> 15.333333
A38: =AVERAGE(B12,D12,F12,H12,J12,L12,N12,P12,R12,T12,V12,X12,Z12,AB12,AD12,AF12) -> 30.666667
A39: =AVERAGE(B13,D13,F13,H13,J13,L13,N13,P13,R13,T13,V13,X13,Z13,AB13,AD13,AF13) -> 39.916667
... A44: =AVERAGE(B18,D18,F18,H18,J18,L18,N18,P18,R18,T18,V18,X18,Z18,AB18,AD18,AF18) -> 152.72727

Sheet Average Time Correct
A1: 1 | C1: 4 | D1: 17 | E1: 5 | G1: 6 | I1: 8 | J1: 69 | K1: 11 | M1: 12 | O1: 13 | Q1: 14 | R1: 65 | S1: 15 | U1: 16 | W1: 17 | X1: 91 | Y1: 19 | Z1: 19 | AA1: 20 | AB1: 75 | AC1: 22 | AD1: 187 | AE1: 23 | AF1: 269 | AG1: 24 | AH1: 65 | AI1: 27 | AJ1: 152 | AK1: 28 | AL1: 29 | AM1: 30 | AN1: 19 | AO1: 32 | AP1: 20 | AQ1: 33 | AR1: 12 | AS1: 36 | AT1: 131 | AU1: 38 | AV1: 174 | AW1: 42 | AX1: 110 | AY1: 43 | AZ1: 133 | BA1: 45 | BB1: 80 | BC1: 47 | BD1: 59 | BE1: 48 | BF1: 76 | BG1: 49 | BH1: 48 | BI1: 52 | BJ1: 274 | BK1: 54 | BL1: 574 | BM1: 55 | BN1: 293 | BO1: 57 | BP1: 30 | BQ1: 58 | BR1: 46 | BS1: 62 | BT1: 30 | BU1: 63 | BV1: 23 | BW1: 64 | BX1: 116
A2: 1 | C2: 4 | D2: 17 | E2: 5 | G2: 6 | I2: 8 | J2: 34 | K2: 11 | M2: 12 | O2: 13 | Q2: 14 | R2: 20 | S2: 15 | U2: 16 | W2: 17 | X2: 18 | Y2: 19 | Z2: 25 | AA2: 20 | AB2: 14 | AC2: 22 | AD2: 29 | AE2: 23 | AF2: 34 | AG2: 24 | AH2: 39 | AI2: 27 | AJ2: 127 | AM2: 30 | AN2: 20 | AO2: 32 | AP2: 10 | AQ2: 33 | AR2: 21 | AS2: 36 | AT2: 84 | AU2: 38 | AV2: 31 | AW2: 42 | AX2: 118 | AY2: 43 | AZ2: 62 | BA2: 45 | BB2: 25 | BC2: 47 | BD2: 33 | BE2: 48 | BF2: 70 | BG2: 49 | BH2: 70 | BI2: 52 | BJ2: 22 | BK2: 54 | BL2: 44 | BM2: 55 | BN2: 38 | BO2: 57 | BP2: 25 | BQ2: 58 | BR2: 50 | BS2: 62 | BT2: 125 | BU2: 63 | BV2: 60 | BW2: 64 | BX2: 63 | BY2: 65 | BZ2: 32 | CA2: 68 | CB2: 126 | CC2: 73 | CD2: 110 | CE2: 74 | CF2: 96 | CG2: 75 | CH2: 42 | CI2: 78 | CJ2: 250 | CK2: 79 | CL2: 45 | CM2: 80 | CN2: 39 | CO2: 81 | CP2: 85 | CQ2: 82 | CR2: 346 | CS2: 83 | CT2: 96 | CU2: 84 | CV2: 36 | CW2: 85 | CX2: 54 | CY2: 86 | CZ2: 28 | DA2: 87 | DB2: 80
A3: 1 | C3: 4 | D3: 33 | E3: 5 | G3: 6 | I3: 8 | J3: 83 | K3: 11 | M3: 12 | O3: 13 | Q3: 14 | R3: 59 | S3: 15 | U3: 16 | W3: 17 | X3: 17 | Y3: 19 | Z3: 44 | AA3: 20 | AB3: 10 | AC3: 22 | AD3: 17 | AE3: 23 | AF3: 29 | AG3: 24 | AH3: 53 | AI3: 27 | AJ3: 82 | AM3: 30 | AN3: 13 | AO3: 32 | AP3: 11 | AQ3: 33 | AR3: 12 | AS3: 36 | AT3: 43 | AU3: 38 | AV3: 48 | AW3: 42 | AX3: 26 | AY3: 43 | AZ3: 48 | BA3: 45 | BB3: 53 | BC3: 47 | BD3: 24 | BE3: 48 | BF3: 70 | BG3: 49 | BH3: 63 | BI3: 52 | BJ3: 27 | BK3: 54 | BL3: 21 | BM3: 55 | BN3: 18 | BO3: 57 | BP3: 27 | BQ3: 58 | BR3: 31 | BS3: 62 | BT3: 37 | BU3: 63 | BV3: 24 | BW3: 64 | BX3: 42 | BY3: 65 | BZ3: 19 | CA3: 68 | CB3: 66 | CC3: 73 | CD3: 60 | CE3: 74 | CF3: 26 | CG3: 75 | CH3: 57 | CI3: 78 | CJ3: 175 | CK3: 79 | CL3: 24 | CM3: 80 | CN3: 63 | CO3: 81 | CP3: 69 | CQ3: 82 | CR3: 61 | CS3: 83 | CT3: 51 | CU3: 84 | CV3: 13 | CW3: 85 | CX3: 35 | CY3: 86 | CZ3: 11 | DA3: 87 | DB3: 31
A4: 1 | C4: 4 | D4: 106 | E4: 5 | G4: 6 | I4: 8 | J4: 87 | K4: 11 | M4: 12 | O4: 13 | Q4: 14 | R4: 71 | S4: 15 | U4: 16 | W4: 17 | X4: 42 | Y4: 19 | Z4: 25 | AA4: 20 | AB4: 13 | AC4: 22 | AD4: 16 | AE4: 23 | AF4: 31 | AG4: 24 | AH4: 24 | AI4: 27 | AJ4: 186 | AM4: 30 | AN4: 36 | AO4: 32 | AP4: 25 | AQ4: 33 | AR4: 41 | AS4: 36 | AT4: 51 | AU4: 38 | AV4: 72 | AW4: 42 | AX4: 43 | AY4: 43 | AZ4: 46 | BA4: 45 | BB4: 29 | BC4: 47 | BD4: 20 | BE4: 48 | BF4: 36 | BG4: 49 | BH4: 16 | BI4: 52 | BJ4: 360 | BK4: 54 | BL4: 32 | BM4: 55 | BN4: 40 | BO4: 57 | BP4: 57 | BQ4: 58 | BR4: 35 | BS4: 62 | BT4: 95 | BU4: 63 | BV4: 21 | BW4: 64 | BX4: 50 | BY4: 65 | BZ4: 15 | CA4: 68 | CB4: 205 | CC4: 73 | CD4: 17 | CE4: 74 | CF4: 21 | CG4: 75 | CH4: 38 | CI4: 78 | CJ4: 129 | CK4: 79 | CL4: 40 | CM4: 80 | CN4: 13 | CO4: 81 | CP4: 24 | CQ4: 82 | CR4: 20 | CS4: 83 | CT4: 57 | CU4: 84 | CV4: 106 | CW4: 85 | CX4: 47 | CY4: 86 | CZ4: 22 | DA4: 87 | DB4: 25
A5: 1 | C5: 4 | D5: 73 | E5: 5 | G5: 6 | I5: 8 | J5: 13 | K5: 11 | M5: 12 | O5: 13 | Q5: 14 | R5: 16 | S5: 15 | U5: 16 | W5: 17 | X5: 47 | Y5: 19 | Z5: 33 | AA5: 20 | AB5: 21 | AC5: 22 | AD5: 43 | AE5: 23 | AF5: 39 | AG5: 24 | AH5: 22 | AI5: 27 | AJ5: 27 | AM5: 30 | AN5: 19 | AO5: 32 | AP5: 27 | AQ5: 33 | AR5: 52 | AS5: 36 | AT5: 19 | AU5: 38 | AV5: 26 | AW5: 42 | AX5: 40 | AY5: 43 | AZ5: 22 | BA5: 45 | BB5: 42 | BC5: 47 | BD5: 25 | BE5: 48 | BF5: 27 | BG5: 49 | BH5: 10 | BI5: 52 | BJ5: 52 | BK5: 54 | BL5: 204 | BM5: 55 | BN5: 13 | BO5: 57 | BP5: 30 | BQ5: 58 | BR5: 35 | BS5: 62 | BT5: 210 | BU5: 63 | BV5: 10 | BW5: 64 | BX5: 12 | BY5: 65 | BZ5: 25 | CA5: 68 | CB5: 195 | CC5: 73 | CD5: 17 | CE5: 74 | CF5: 16 | CG5: 75 | CH5: 31 | CI5: 78 | CJ5: 55 | CK5: 79 | CL5: 29 | CM5: 80 | CN5: 60 | CO5: 81 | CP5: 16 | CQ5: 82 | CR5: 624 | CS5: 83 | CT5: 20 | CU5: 84 | CV5: 8 | CW5: 85 | CX5: 368 | CY5: 86 | CZ5: 64 | DA5: 87 | DB5: 75
A6: 1 | C6: 4 | D6: 7 | E6: 5 | G6: 6 | I6: 8 | J6: 28 | K6: 11 | M6: 12 | O6: 13 | Q6: 14 | R6: 16 | S6: 15 | U6: 16 | W6: 17 | X6: 15 | Y6: 19 | Z6: 78 | AA6: 20 | AB6: 13 | AC6: 22 | AD6: 11 | AE6: 23 | AF6: 25 | AG6: 24 | AH6: 20 | AI6: 27 | AJ6: 16 | AM6: 30 | AN6: 11 | AO6: 32 | AP6: 18 | AQ6: 33 | AR6: 6 | AS6: 36 | AT6: 30 | AU6: 38 | AV6: 18 | AW6: 42 | AX6: 33 | AY6: 43 | AZ6: 19 | BA6: 45 | BB6: 17 | BC6: 47 | BD6: 16 | BE6: 48 | BF6: 36 | BG6: 49 | BH6: 10 | BI6: 52 | BJ6: 22 | BK6: 54 | BL6: 15 | BM6: 55 | BN6: 11 | BO6: 57 | BP6: 13 | BQ6: 58 | BR6: 21 | BS6: 62 | BT6: 23 | BU6: 63 | BV6: 14 | BW6: 64 | BX6: 18 | BY6: 65 | BZ6: 44 | CA6: 68 | CB6: 17 | CC6: 73 | CD6: 23 | CE6: 74 | CF6: 31 | CG6: 75 | CH6: 36 | CI6: 78 | CJ6: 36 | CK6: 79 | CL6: 23 | CM6: 80 | CN6: 22 | CO6: 81 | CP6: 17 | CQ6: 82 | CR6: 13 | CS6: 83 | CT6: 22 | CU6: 84 | CV6: 6 | CW6: 85 | CX6: 37 | CY6: 86 | CZ6: 36 | DA6: 87 | DB6: 24
A7: 1 | C7: 4 | D7: 15 | E7: 5 | G7: 6 | I7: 8 | J7: 28 | K7: 11 | M7: 12 | O7: 13 | Q7: 14 | R7: 11 | S7: 15 | U7: 16 | W7: 17 | X7: 22 | Y7: 19 | Z7: 12 | AA7: 20 | AB7: 10 | AC7: 22 | AD7: 10 | AE7: 23 | AF7: 15 | AG7: 24 | AH7: 17 | AI7: 27 | AJ7: 10 | AM7: 30 | AN7: 8 | AO7: 32 | AP7: 19 | AQ7: 33 | AR7: 19 | AS7: 36 | AT7: 15 | AU7: 38 | AV7: 15 | AW7: 42 | AX7: 17 | AY7: 43 | AZ7: 13 | BA7: 45 | BB7: 10 | BC7: 47 | BD7: 34 | BE7: 48 | BF7: 18 | BG7: 49 | BH7: 6 | BI7: 52 | BJ7: 13 | BK7: 54 | BL7: 43 | BM7: 55 | BN7: 10 | BO7: 57 | BP7: 32 | BQ7: 58 | BR7: 26 | BS7: 62 | BT7: 13 | BU7: 63 | BV7: 8 | BW7: 64 | BX7: 8 | BY7: 65 | BZ7: 12 | CA7: 68 | CB7: 128 | CC7: 73 | CD7: 12 | CE7: 74 | CF7: 40 | CG7: 75 | CH7: 76 | CI7: 78 | CJ7: 27 | CK7: 79 | CL7: 18 | CM7: 80 | CN7: 12 | CO7: 81 | CP7: 16 | CQ7: 82 | CR7: 44 | CS7: 83 | CT7: 22 | CU7: 84 | CV7: 9 | CW7: 85 | CX7: 20 | CY7: 86 | CZ7: 9 | DA7: 87 | DB7: 17
A8: 1 | C8: 4 | D8: 11 | E8: 5 | G8: 6 | I8: 8 | J8: 17 | K8: 11 | M8: 12 | O8: 13 | Q8: 14 | R8: 7 | S8: 15 | U8: 16 | W8: 17 | X8: 21 | Y8: 19 | Z8: 16 | AA8: 20 | AB8: 13 | AC8: 22 | AD8: 11 | AE8: 23 | AF8: 16 | AG8: 24 | AH8: 21 | AI8: 27 | AJ8: 135 | AM8: 30 | AN8: 6 | AO8: 32 | AP8: 17 | AQ8: 33 | AR8: 14 | AS8: 36 | AT8: 17 | AU8: 38 | AV8: 11 | AW8: 42 | AX8: 12 | AY8: 43 | AZ8: 14 | BA8: 45 | BB8: 8 | BC8: 47 | BD8: 21 | BE8: 48 | BF8: 18 | BG8: 49 | BH8: 8 | BI8: 52 | BJ8: 14 | BK8: 54 | BL8: 12 | BM8: 55 | BN8: 10 | BO8: 57 | BP8: 12 | BQ8: 58 | BR8: 25 | BS8: 62 | BT8: 13 | BU8: 63 | BV8: 7 | BW8: 64 | BX8: 20 | BY8: 65 | BZ8: 9 | CA8: 68 | CB8: 24 | CC8: 73 | CD8: 18 | CE8: 74 | CF8: 11 | CG8: 75 | CH8: 22 | CI8: 78 | CJ8: 21 | CK8: 79 | CL8: 10 | CM8: 80 | CN8: 8 | CO8: 81 | CP8: 11 | CQ8: 82 | CR8: 11 | CS8: 83 | CT8: 23 | CU8: 84 | CV8: 7 | CW8: 85 | CX8: 20 | CY8: 86 | CZ8: 17 | DA8: 87 | DB8: 17
A9: 1 | C9: 4 | D9: 8 | E9: 5 | G9: 6 | I9: 8 | J9: 24 | K9: 11 | M9: 12 | O9: 13 | Q9: 14 | R9: 10 | S9: 15 | U9: 16 | W9: 17 | X9: 9 | Y9: 19 | Z9: 13 | AA9: 20 | AB9: 11 | AC9: 22 | AD9: 12 | AE9: 23 | AF9: 28 | AG9: 24 | AH9: 10 | AI9: 27 | AJ9: 83 | AM9: 30 | AN9: 9 | AO9: 32 | AP9: 18 | AQ9: 33 | AR9: 15 | AS9: 36 | AT9: 15 | AU9: 38 | AV9: 16 | AW9: 42 | AX9: 22 | AY9: 43 | AZ9: 12 | BA9: 45 | BB9: 14 | BC9: 47 | BD9: 10 | BE9: 48 | BF9: 18 | BG9: 49 | BH9: 10 | BI9: 52 | BJ9: 14 | BK9: 54 | BL9: 15 | BM9: 55 | BN9: 7 | BO9: 57 | BP9: 13 | BQ9: 58 | BR9: 18 | BS9: 62 | BT9: 102 | BU9: 63 | BV9: 6 | BW9: 64 | BX9: 15 | BY9: 65 | BZ9: 14 | CA9: 68 | CB9: 12 | CC9: 73 | CD9: 10 | CE9: 74 | CF9: 20 | CG9: 75 | CH9: 25 | CI9: 78 | CJ9: 34 | CK9: 79 | CL9: 12 | CM9: 80 | CN9: 15 | CO9: 81 | CP9: 14 | CQ9: 82 | CR9: 11 | CS9: 83 | CT9: 31 | CU9: 84 | CV9: 6 | CW9: 85 | CX9: 17 | CY9: 86 | CZ9: 10 | DA9: 87 | DB9: 13
A10: 1 | C10: 4 | D10: 6 | E10: 5 | G10: 6 | I10: 8 | J10: 12 | K10: 11 | M10: 12 | O10: 13 | Q10: 14 | R10: 13 | S10: 15 | U10: 16 | W10: 17 | X10: 6 | Y10: 19 | Z10: 59 | AA10: 20 | AB10: 6 | AC10: 22 | AD10: 14 | AE10: 23 | AF10: 11 | AG10: 24 | AH10: 15 | AI10: 27 | AJ10: 53 | AM10: 30 | AN10: 7 | AO10: 32 | AP10: 27 | AQ10: 33 | AR10: 81 | AS10: 36 | AT10: 16 | AU10: 38 | AV10: 157 | AW10: 42 | AX10: 9 | AY10: 43 | AZ10: 9 | BA10: 45 | BB10: 10 | BC10: 47 | BD10: 13 | BE10: 48 | BF10: 15 | BG10: 49 | BH10: 10 | BI10: 52 | BJ10: 18 | BK10: 54 | BL10: 13 | BM10: 55 | BN10: 8 | BO10: 57 | BP10: 11 | BQ10: 58 | BR10: 20 | BS10: 62 | BT10: 67 | BU10: 63 | BV10: 5 | BW10: 64 | BX10: 6 | BY10: 65 | BZ10: 15 | CA10: 68 | CB10: 10 | CC10: 73 | CD10: 12 | CE10: 74 | CF10: 16 | CG10: 75 | CH10: 34 | CI10: 78 | CJ10: 13 | CK10: 79 | CL10: 21 | CM10: 80 | CN10: 15 | CO10: 81 | CP10: 17 | CQ10: 82 | CR10: 8 | CS10: 83 | CT10: 16 | CU10: 84 | CV10: 22 | CW10: 85 | CX10: 18 | CY10: 86 | CZ10: 8 | DA10: 87 | DB10: 15
A11: 1 | C11: 4 | D11: 16 | G11: 6 | I11: 8 | J11: 24 | K11: 11 | M11: 12 | O11: 13 | Q11: 14 | R11: 6 | S11: 15 | U11: 16 | W11: 17 | X11: 8 | Y11: 19 | Z11: 8 | AA11: 20 | AB11: 6 | AC11: 22 | AD11: 26 | AE11: 23 | AF11: 8 | AG11: 24 | AH11: 6 | AI11: 27 | AJ11: 29 | AM11: 30 | AN11: 5 | AO11: 32 | AP11: 29 | AQ11: 33 | AR11: 16 | AS11: 36 | AT11: 13 | AU11: 38 | AV11: 15 | AW11: 42 | AX11: 9 | AY11: 43 | AZ11: 14 | BA11: 45 | BB11: 14 | BC11: 47 | BD11: 22 | BE11: 48 | BF11: 11 | BG11: 49 | BH11: 26 | BI11: 52 | BJ11: 8 | BK11: 54 | BL11: 8 | BM11: 55 | BN11: 7 | BO11: 57 | BP11: 154 | BQ11: 58 | BR11: 8 | BS11: 62 | BT11: 146 | BU11: 63 | BV11: 6 | BW11: 64 | BX11: 6 | BY11: 65 | BZ11: 10 | CA11: 68 | CB11: 8 | CC11: 73 | CD11: 8 | CE11: 74 | CF11: 9 | CG11: 75 | CH11: 9 | CI11: 78 | CJ11: 18 | CK11: 79 | CL11: 13 | CM11: 80 | CN11: 20 | CO11: 81 | CP11: 11 | CQ11: 82 | CR11: 18 | CS11: 83 | CT11: 16 | CU11: 84 | CV11: 12 | CW11: 85 | CX11: 36 | CY11: 86 | CZ11: 5 | DA11: 87 | DB11: 6
